Exception in Tkinter callback
Traceback (most recent call last):
  File "/usr/lib/python2.7/lib-tk/Tkinter.py", line 1473, in __call__
    return self.func(*args)
  File "gui.py", line 472, in generate_netlist_errors
    self.generate_netlist()
  File "gui.py", line 349, in generate_netlist
    self.getImpe()
  File "gui.py", line 305, in getImpe
    A=cmath.exp(-Psi*h[i1])
TypeError: 'int' object has no attribute '__getitem__'
