Exception in Tkinter callback
Traceback (most recent call last):
  File "/usr/lib/python2.7/lib-tk/Tkinter.py", line 1473, in __call__
    return self.func(*args)
  File "gui.py", line 545, in generate_netlist_errors
    except e:
NameError: global name 'e' is not defined
